Workbook
Name л: #REF!
Name л: #REF!
Name о: #REF!
Name о: #REF!
Name Сумма: #REF!
Name Сумма: #REF!
Name Сумма: #REF!
Name Сумма1: #REF!
Name Сумма1: #REF!
Name Сумма1: #REF!

Sheet HeadRock
A7: Сентябрь 2026 | K7: =G806 -> 0
A8: Изображение | B8: Артикул | C8: Наименование | D8: Единиц в комплекте | E8: Штук/ комплектов во внутр. коробке | F8: Штук/ комплектов в коробке | G8: Цена за штуку/комплект в руб. с НДС) | H8: Минимальное количество заказа | I8: Ваш заказ, штук/комплектов | J8: Комплекты в штуках | K8: Сумма заказа | L8: Штрих-код (штука) | M8: Штрих-код (комплект) | N8: Штрих-код (коробка)
B9: Бур по бетону SDS+
B10: 402-010-6110 | C10: Бур по бетону SDS+ (6x110) | D10: 1 | E10: 50 | F10: 500 | G10: ='-'!G10 -> 47.18 | J10: - | K10: =G10*I10 -> 0 | L10: 4673732410025 | N10: 4673732410032
B11: 402-010-6160 | C11: Бур по бетону SDS+ (6x160) | D11: 1 | E11: 50 | F11: 500 | G11: ='-'!G11 -> 50.05 | J11: - | K11: =G11*I11 -> 0 | L11: 4673732410049 | N11: 4673732410056
B12: 402-010-6210 | C12: Бур по бетону SDS+ (6x210) | D12: 1 | E12: 50 | F12: 300 | G12: ='-'!G12 -> 61.88 | J12: - | K12: =G12*I12 -> 0 | L12: 4673732410063 | N12: 4673732410070
B13: 402-010-6260 | C13: Бур по бетону SDS+ (6x260) | D13: 1 | E13: 50 | F13: 250 | G13: ='-'!G13 -> 76.86 | J13: - | K13: =G13*I13 -> 0 | L13: 4673732410087 | N13: 4673732410094
B14: 402-010-6310 | C14: Бур по бетону SDS+ (6x310) | D14: 1 | E14: 50 | F14: 200 | G14: ='-'!G14 -> 83.19 | J14: - | K14: =G14*I14 -> 0 | L14: 4673732410100 | N14: 4673732410117
B15: 402-010-6350 | C15: Бур по бетону SDS+ (6x350) | D15: 1 | E15: 50 | F15: 200 | G15: ='-'!G15 -> 96.51 | J15: - | K15: =G15*I15 -> 0 | L15: 4673732410124 | N15: 4673732410131
B16: 402-010-6410 | C16: Бур по бетону SDS+ (6x410) РАСПРОДАЖА! | D16: 1 | E16: 50 | F16: 200 | G16: ='-'!G16 -> 102.69 | J16: - | K16: =G16*I16 -> 0 | L16: 4673732410148 | N16: 4673732410155
B17: 402-010-8110 | C17: Бур по бетону SDS+ (8x110) | D17: 1 | E17: 50 | F17: 500 | G17: ='-'!G17 -> 47.5 | J17: - | K17: =G17*I17 -> 0 | L17: 4673732410162 | N17: 4673732410179
B18: 402-010-8160 | C18: Бур по бетону SDS+ (8x160) | D18: 1 | E18: 50 | F18: 500 | G18: ='-'!G18 -> 61.88 | J18: - | K18: =G18*I18 -> 0 | L18: 4673732410186 | N18: 4673732410193
B19: 402-010-8210 | C19: Бур по бетону SDS+ (8x210) | D19: 1 | E19: 50 | F19: 250 | G19: ='-'!G19 -> 75.13 | J19: - | K19: =G19*I19 -> 0 | L19: 4673732410209 | N19: 4673732410216
B20: 402-010-8260 | C20: Бур по бетону SDS+ (8x260) | D20: 1 | E20: 50 | F20: 200 | G20: ='-'!G20 -> 78.75 | J20: - | K20: =G20*I20 -> 0 | L20: 4673732410223 | N20: 4673732410230
B21: 402-010-8310 | C21: Бур по бетону SDS+ (8x310) | D21: 1 | E21: 50 | F21: 100 | G21: ='-'!G21 -> 86.25 | J21: - | K21: =G21*I21 -> 0 | L21: 4673732410247 | N21: 4673732410254
... B92: 402-010-22460 | C92: Бур по бетону SDS+ (22х460) | D92: 1 | E92: 25 | F92: 25 | G92: ='-'!G92 -> 372.64 | J92: - | K92: =G92*I92 -> 0 | L92: 4673759127746 | N92: 4673759127753
B93: Зубило SDS+
B94: 411-010-1425020 | C94: Зубило SDS+ (14x250x20) | D94: 1 | E94: 10 | F94: 100 | G94: ='-'!G94 -> 126.39 | J94: - | K94: =G94*I94 -> 0 | L94: 4673732410780 | N94: 4673732410797
B95: 411-010-1425050 | C95: Зубило SDS+ (14x250x50) | D95: 1 | E95: 10 | F95: 100 | G95: ='-'!G95 -> 183.48 | J95: - | K95: =G95*I95 -> 0 | L95: 4673732410803 | N95: 4673732410810
B96: 411-010-1440020 | C96: Зубило SDS+ (14x400x20) | D96: 1 | E96: 10 | F96: 50 | G96: ='-'!G96 -> 216.25 | J96: - | K96: =G96*I96 -> 0 | L96: 4673768180541 | N96: 4673768180558
B97: 411-010-1440050 | C97: Зубило SDS+ (14x400x50) | D97: 1 | E97: 10 | F97: 50 | G97: ='-'!G97 -> 287.56 | J97: - | K97: =G97*I97 -> 0 | L97: 4673768180565 | N97: 4673768180572
B98: 411-010-1460020 | C98: Зубило SDS+ (14x600x20) | D98: 1 | E98: 5 | F98: 25 | G98: ='-'!G98 -> 310.56 | J98: - | K98: =G98*I98 -> 0 | L98: 4673768180589 | N98: 4673768180596
B99: 411-010-1460050 | C99: Зубило SDS+ (14x600x50) | D99: 1 | E99: 5 | F99: 25 | G99: ='-'!G99 -> 411.9 | J99: - | K99: =G99*I99 -> 0 | L99: 4673768180602 | N99: 4673768180619
B100: Коронка по бетону SDS+
B101: 422-010-30 | C101: Коронка по бетону SDS+ D30 | D101: 1 | E101: / | F101: 50 | G101: ='-'!G101 -> 351.13 | J101: - | K101: =G101*I101 -> 0 | L101: 4673759127760 | N101: 4673759127777
B102: 422-010-35 | C102: Коронка по бетону SDS+ D35 | D102: 1 | E102: / | F102: 50 | G102: ='-'!G102 -> 364.48 | J102: - | K102: =G102*I102 -> 0 | L102: 4673759127784 | N102: 4673759127791
B103: 422-010-40 | C103: Коронка по бетону SDS+ D40 | D103: 1 | E103: / | F103: 50 | G103: ='-'!G103 -> 438.6 | J103: - | K103: =G103*I103 -> 0 | L103: 4673759127807 | N103: 4673759127814
B104: 422-010-45 | C104: Коронка по бетону SDS+ D45 | D104: 1 | E104: / | F104: 50 | G104: ='-'!G104 -> 547 | J104: - | K104: =G104*I104 -> 0 | L104: 4673732414535 | N104: 4673732414542
B105: 422-010-50 | C105: Коронка по бетону SDS+ D50 | D105: 1 | E105: / | F105: 50 | G105: ='-'!G105 -> 586.84 | J105: - | K105: =G105*I105 -> 0 | L105: 4673732414566 | N105: 4673732414559
B106: 422-010-55 | C106: Коронка по бетону SDS+ D55 | D106: 1 | E106: / | F106: 20 | G106: ='-'!G106 -> 481.84 | J106: - | K106: =G106*I106 -> 0 | L106: 4673732414597 | N106: 4673732414603
B107: 422-010-60 | C107: Коронка по бетону SDS+ D60 | D107: 1 | E107: / | F107: 20 | G107: ='-'!G107 -> 506.55 | J107: - | K107: =G107*I107 -> 0 | L107: 4673732414610 | N107: 4673732414627
B108: 422-010-65 | C108: Коронка по бетону SDS+ D65 | D108: 1 | E108: / | F108: 20 | G108: ='-'!G108 -> 647.19 | J108: - | K108: =G108*I108 -> 0 | L108: 4673732410827 | N108: 4673732410834
B109: 422-010-68 | C109: Коронка по бетону SDS+ D68 | D109: 1 | E109: / | F109: 20 | G109: ='-'!G109 -> 700.16 | J109: - | K109: =G109*I109 -> 0 | L109: 4673732410841 | N109: 4673732410858
B110: 422-010-70 | C110: Коронка по бетону SDS+ D70 | D110: 1 | E110: / | F110: 20 | G110: ='-'!G110 -> 734.95 | J110: - | K110: =G110*I110 -> 0 | L110: 4673732410865 | N110: 4673732410872
B111: 422-010-75 | C111: Коронка по бетону SDS+ D75 | D111: 1 | E111: / | F111: 20 | G111: ='-'!G111 -> 630.09 | J111: - | K111: =G111*I111 -> 0 | L111: 4673732410889 | N111: 4673732410896
B112: 422-010-100 | C112: Коронка по бетону SDS+ D100 | D112: 1 | E112: / | F112: 10 | G112: ='-'!G112 -> 1114.4 | J112: - | K112: =G112*I112 -> 0 | L112: 4673732410902 | N112: 4673732410919
... B116: 422-010-150 | C116: Коронка по бетону SDS+ D150 | D116: 1 | E116: / | F116: 10 | G116: ='-'!G116 -> 1985.66 | J116: - | K116: =G116*I116 -> 0 | L116: 4673759127845 | N116: 4673759127852
B117: Коронка алмазная по бетону (безударные)
B118: 634-708-068 | C118: Коронка алмазная по бетону 68мм (безударная) | D118: 1 | E118: / | F118: 30 | G118: ='-'!G118 -> 1876.56 | J118: - | K118: =G118*I118 -> 0 | L118: 4673768180626 | N118: 4673768180633
B119: 634-708-072 | C119: Коронка алмазная по бетону 72мм (безударная) | D119: 1 | E119: / | F119: 30 | G119: ='-'!G119 -> 2024.4 | J119: - | K119: =G119*I119 -> 0 | L119: 4673768180640 | N119: 4673768180657
...

Sheet -
O1: Корректировка 03 Сентябрь
V3: FALSE | W3: Заграничный клиент, минус НДС
V4: FALSE | W4: Включить стоимость доставки в цену
V5: FALSE | W5: Оплата за наличные
A7: Сентябрь 2026 | J7: =G806 -> 0 | O7: Стоимость доставки по РФ за кг. | P7: 16 | V7: расчёт | AB7: Вес
A8: Изображение | B8: Артикул | C8: Наименование | D8: Единиц в комплекте | E8: Штук/ комплектов во внутр. коробке | F8: Штук/ комплектов в коробке | G8: Цена за штуку/комплект в руб. с НДС) | H8: Ваш заказ, штук/комплектов | I8: Комплекты в штуках | J8: Сумма заказа | K8: Штрих-код (штука) | L8: Штрих-код (комплект) | M8: Штрих-код (коробка) | O8: Скидка | P8: 0 | Q8: индивидуальная скидка | T8: min для ручного ввода | V8: коэфф max | W8: цена без скидки | X8: коэфф % | Y8: без округления | Z8: с округлением | AB8: Брутто за шт. | AC8: Итого, кг. | AD8: Стоимость доставки | AE8: Стоимость доставки за шт. | AF8: округление до 2х знаков | AH8: Округление до 2 знаков | AJ8: Если включить в стоимость доставку | AL8: Если оплата за наличку (-10%) | AN8: Если заграничный клиент (-НДС)
B9: Бур по бетону SDS+ | O9: Бур по бетону SDS+
B10: 402-010-6110 | C10: Бур по бетону SDS+ (6x110) | D10: 1 | E10: 50 | F10: 500 | G10: =AH10 -> 47.18 | I10: - | J10: =G10*H10 -> 0 | K10: 4673732410025 | M10: 4673732410032 | P10: =$P$8 -> 0 | R10: =IF(Q10>0,Q10,P10) -> 0 | S10: =IF(P10>18,"ПЕРЕБОР","-") -> - | T10: 37.74375 | V10: 1.25 | W10: =T10*V10 -> 47.179688 | X10: =R10*0.01 -> 0 | Y10: =W10-(W10*X10) -> 47.179688 | Z10: =ROUND(Y10,2) -> 47.18 | AB10: 0.042 | AC10: =H10*AB10 -> 0 | AD10: =AC10*$P$7 -> 0 | AE10: =AB10*$P$7 -> 0.672 | AF10: =ROUND(AE10,2) -> 0.67 | AH10: =ROUNDUP(AN10,2) -> 47.18 | AJ10: =IF($V$4,AL10+AF10,AL10) -> 47.18 | AL10: =IF($V$5,Z10-Z10*10%,Z10) -> 47.18 | AN10: =IF($V$3,AJ10-((AJ10*1.18031)-AJ10),AJ10) -> 47.18
B11: 402-010-6160 | C11: Бур по бетону SDS+ (6x160) | D11: 1 | E11: 50 | F11: 500 | G11: =AH11 -> 50.05 | I11: - | J11: =G11*H11 -> 0 | K11: 4673732410049 | M11: 4673732410056 | P11: =$P$8 -> 0 | R11: =IF(Q11>0,Q11,P11) -> 0 | S11: =IF(P11>18,"ПЕРЕБОР","-") -> - | T11: 40.03875 | V11: 1.25 | W11: =T11*V11 -> 50.048438 | X11: =R11*0.01 -> 0 | Y11: =W11-(W11*X11) -> 50.048438 | Z11: =ROUND(Y11,2) -> 50.05 | AB11: 0.05 | AC11: =H11*AB11 -> 0 | AD11: =AC11*$P$7 -> 0 | AE11: =AB11*$P$7 -> 0.8 | AF11: =ROUND(AE11,2) -> 0.8 | AH11: =ROUNDUP(AN11,2) -> 50.05 | AJ11: =IF($V$4,AL11+AF11,AL11) -> 50.05 | AL11: =IF($V$5,Z11-Z11*10%,Z11) -> 50.05 | AN11: =IF($V$3,AJ11-((AJ11*1.18031)-AJ11),AJ11) -> 50.05
B12: 402-010-6210 | C12: Бур по бетону SDS+ (6x210) | D12: 1 | E12: 50 | F12: 300 | G12: =AH12 -> 61.88 | I12: - | J12: =G12*H12 -> 0 | K12: 4673732410063 | M12: 4673732410070 | P12: =$P$8 -> 0 | R12: =IF(Q12>0,Q12,P12) -> 0 | S12: =IF(P12>18,"ПЕРЕБОР","-") -> - | T12: 49.5 | V12: 1.25 | W12: =T12*V12 -> 61.875 | X12: =R12*0.01 -> 0 | Y12: =W12-(W12*X12) -> 61.875 | Z12: =ROUND(Y12,2) -> 61.88 | AB12: 0.056666667 | AC12: =H12*AB12 -> 0 | AD12: =AC12*$P$7 -> 0 | AE12: =AB12*$P$7 -> 0.90666667 | AF12: =ROUND(AE12,2) -> 0.91 | AH12: =ROUNDUP(AN12,2) -> 61.88 | AJ12: =IF($V$4,AL12+AF12,AL12) -> 61.88 | AL12: =IF($V$5,Z12-Z12*10%,Z12) -> 61.88 | AN12: =IF($V$3,AJ12-((AJ12*1.18031)-AJ12),AJ12) -> 61.88
B13: 402-010-6260 | C13: Бур по бетону SDS+ (6x260) | D13: 1 | E13: 50 | F13: 250 | G13: =AH13 -> 76.86 | I13: - | J13: =G13*H13 -> 0 | K13: 4673732410087 | M13: 4673732410094 | P13: =$P$8 -> 0 | R13: =IF(Q13>0,Q13,P13) -> 0 | S13: =IF(P13>18,"ПЕРЕБОР","-") -> - | T13: 61.49 | V13: 1.25 | W13: =T13*V13 -> 76.8625 | X13: =R13*0.01 -> 0 | Y13: =W13-(W13*X13) -> 76.8625 | Z13: =ROUND(Y13,2) -> 76.86 | AB13: 0.072 | AC13: =H13*AB13 -> 0 | AD13: =AC13*$P$7 -> 0 | AE13: =AB13*$P$7 -> 1.152 | AF13: =ROUND(AE13,2) -> 1.15 | AH13: =ROUNDUP(AN13,2) -> 76.86 | AJ13: =IF($V$4,AL13+AF13,AL13) -> 76.86 | AL13: =IF($V$5,Z13-Z13*10%,Z13) -> 76.86 | AN13: =IF($V$3,AJ13-((AJ13*1.18031)-AJ13),AJ13) -> 76.86
B14: 402-010-6310 | C14: Бур по бетону SDS+ (6x310) | D14: 1 | E14: 50 | F14: 200 | G14: =AH14 -> 83.19 | I14: - | J14: =G14*H14 -> 0 | K14: 4673732410100 | M14: 4673732410117 | P14: =$P$8 -> 0 | R14: =IF(Q14>0,Q14,P14) -> 0 | S14: =IF(P14>18,"ПЕРЕБОР","-") -> - | T14: 66.55 | V14: 1.25 | W14: =T14*V14 -> 83.1875 | X14: =R14*0.01 -> 0 | Y14: =W14-(W14*X14) -> 83.1875 | Z14: =ROUND(Y14,2) -> 83.19 | AB14: 0.08 | AC14: =H14*AB14 -> 0 | AD14: =AC14*$P$7 -> 0 | AE14: =AB14*$P$7 -> 1.28 | AF14: =ROUND(AE14,2) -> 1.28 | AH14: =ROUNDUP(AN14,2) -> 83.19 | AJ14: =IF($V$4,AL14+AF14,AL14) -> 83.19 | AL14: =IF($V$5,Z14-Z14*10%,Z14) -> 83.19 | AN14: =IF($V$3,AJ14-((AJ14*1.18031)-AJ14),AJ14) -> 83.19
B15: 402-010-6350 | C15: Бур по бетону SDS+ (6x350) | D15: 1 | E15: 50 | F15: 200 | G15: =AH15 -> 96.51 | I15: - | J15: =G15*H15 -> 0 | K15: 4673732410124 | M15: 4673732410131 | P15: =$P$8 -> 0 | R15: =IF(Q15>0,Q15,P15) -> 0 | S15: =IF(P15>18,"ПЕРЕБОР","-") -> - | T15: 77.21 | V15: 1.25 | W15: =T15*V15 -> 96.5125 | X15: =R15*0.01 -> 0 | Y15: =W15-(W15*X15) -> 96.5125 | Z15: =ROUND(Y15,2) -> 96.51 | AB15: 0.1 | AC15: =H15*AB15 -> 0 | AD15: =AC15*$P$7 -> 0 | AE15: =AB15*$P$7 -> 1.6 | AF15: =ROUND(AE15,2) -> 1.6 | AH15: =ROUNDUP(AN15,2) -> 96.51 | AJ15: =IF($V$4,AL15+AF15,AL15) -> 96.51 | AL15: =IF($V$5,Z15-Z15*10%,Z15) -> 96.51 | AN15: =IF($V$3,AJ15-((AJ15*1.18031)-AJ15),AJ15) -> 96.51
B16: 402-010-6410 | C16: Бур по бетону SDS+ (6x410) РАСПРОДАЖА! | D16: 1 | E16: 50 | F16: 200 | G16: =AH16 -> 102.69 | I16: - | J16: =G16*H16 -> 0 | K16: 4673732410148 | M16: 4673732410155 | P16: =$P$8 -> 0 | R16: =IF(Q16>0,Q16,P16) -> 0 | S16: =IF(P16>18,"ПЕРЕБОР","-") -> - | T16: 82.15 | V16: 1.25 | W16: =T16*V16 -> 102.6875 | X16: =R16*0.01 -> 0 | Y16: =W16-(W16*X16) -> 102.6875 | Z16: =ROUND(Y16,2) -> 102.69 | AB16: 0.1 | AC16: =H16*AB16 -> 0 | AD16: =AC16*$P$7 -> 0 | AE16: =AB16*$P$7 -> 1.6 | AF16: =ROUND(AE16,2) -> 1.6 | AH16: =ROUNDUP(AN16,2) -> 102.69 | AJ16: =IF($V$4,AL16+AF16,AL16) -> 102.69 | AL16: =IF($V$5,Z16-Z16*10%,Z16) -> 102.69 | AN16: =IF($V$3,AJ16-((AJ16*1.18031)-AJ16),AJ16) -> 102.69
B17: 402-010-8110 | C17: Бур по бетону SDS+ (8x110) | D17: 1 | E17: 50 | F17: 500 | G17: =AH17 -> 47.5 | I17: - | J17: =G17*H17 -> 0 | K17: 4673732410162 | M17: 4673732410179 | P17: =$P$8 -> 0 | R17: =IF(Q17>0,Q17,P17) -> 0 | S17: =IF(P17>18,"ПЕРЕБОР","-") -> - | T17: 38 | V17: 1.25 | W17: =T17*V17 -> 47.5 | X17: =R17*0.01 -> 0 | Y17: =W17-(W17*X17) -> 47.5 | Z17: =ROUND(Y17,2) -> 47.5 | AB17: 0.046 | AC17: =H17*AB17 -> 0 | AD17: =AC17*$P$7 -> 0 | AE17: =AB17*$P$7 -> 0.736 | AF17: =ROUND(AE17,2) -> 0.74 | AH17: =ROUNDUP(AN17,2) -> 47.5 | AJ17: =IF($V$4,AL17+AF17,AL17) -> 47.5 | AL17: =IF($V$5,Z17-Z17*10%,Z17) -> 47.5 | AN17: =IF($V$3,AJ17-((AJ17*1.18031)-AJ17),AJ17) -> 47.5
B18: 402-010-8160 | C18: Бур по бетону SDS+ (8x160) | D18: 1 | E18: 50 | F18: 500 | G18: =AH18 -> 61.88 | I18: - | J18: =G18*H18 -> 0 | K18: 4673732410186 | M18: 4673732410193 | P18: =$P$8 -> 0 | R18: =IF(Q18>0,Q18,P18) -> 0 | S18: =IF(P18>18,"ПЕРЕБОР","-") -> - | T18: 49.5 | V18: 1.25 | W18: =T18*V18 -> 61.875 | X18: =R18*0.01 -> 0 | Y18: =W18-(W18*X18) -> 61.875 | Z18: =ROUND(Y18,2) -> 61.88 | AB18: 0.058 | AC18: =H18*AB18 -> 0 | AD18: =AC18*$P$7 -> 0 | AE18: =AB18*$P$7 -> 0.928 | AF18: =ROUND(AE18,2) -> 0.93 | AH18: =ROUNDUP(AN18,2) -> 61.88 | AJ18: =IF($V$4,AL18+AF18,AL18) -> 61.88 | AL18: =IF($V$5,Z18-Z18*10%,Z18) -> 61.88 | AN18: =IF($V$3,AJ18-((AJ18*1.18031)-AJ18),AJ18) -> 61.88
B19: 402-010-8210 | C19: Бур по бетону SDS+ (8x210) | D19: 1 | E19: 50 | F19: 250 | G19: =AH19 -> 75.13 | I19: - | J19: =G19*H19 -> 0 | K19: 4673732410209 | M19: 4673732410216 | P19: =$P$8 -> 0 | R19: =IF(Q19>0,Q19,P19) -> 0 | S19: =IF(P19>18,"ПЕРЕБОР","-") -> - | T19: 60.104 | V19: 1.25 | W19: =T19*V19 -> 75.13 | X19: =R19*0.01 -> 0 | Y19: =W19-(W19*X19) -> 75.13 | Z19: =ROUND(Y19,2) -> 75.13 | AB19: 0.076 | AC19: =H19*AB19 -> 0 | AD19: =AC19*$P$7 -> 0 | AE19: =AB19*$P$7 -> 1.216 | AF19: =ROUND(AE19,2) -> 1.22 | AH19: =ROUNDUP(AN19,2) -> 75.13 | AJ19: =IF($V$4,AL19+AF19,AL19) -> 75.13 | AL19: =IF($V$5,Z19-Z19*10%,Z19) -> 75.13 | AN19: =IF($V$3,AJ19-((AJ19*1.18031)-AJ19),AJ19) -> 75.13
B20: 402-010-8260 | C20: Бур по бетону SDS+ (8x260) | D20: 1 | E20: 50 | F20: 200 | G20: =AH20 -> 78.75 | I20: - | J20: =G20*H20 -> 0 | K20: 4673732410223 | M20: 4673732410230 | P20: =$P$8 -> 0 | R20: =IF(Q20>0,Q20,P20) -> 0 | S20: =IF(P20>18,"ПЕРЕБОР","-") -> - | T20: 63 | V20: 1.25 | W20: =T20*V20 -> 78.75 | X20: =R20*0.01 -> 0 | Y20: =W20-(W20*X20) -> 78.75 | Z20: =ROUND(Y20,2) -> 78.75 | AB20: 0.105 | AC20: =H20*AB20 -> 0 | AD20: =AC20*$P$7 -> 0 | AE20: =AB20*$P$7 -> 1.68 | AF20: =ROUND(AE20,2) -> 1.68 | AH20: =ROUNDUP(AN20,2) -> 78.75 | AJ20: =IF($V$4,AL20+AF20,AL20) -> 78.75 | AL20: =IF($V$5,Z20-Z20*10%,Z20) -> 78.75 | AN20: =IF($V$3,AJ20-((AJ20*1.18031)-AJ20),AJ20) -> 78.75
B21: 402-010-8310 | C21: Бур по бетону SDS+ (8x310) | D21: 1 | E21: 50 | F21: 100 | G21: =AH21 -> 86.25 | I21: - | J21: =G21*H21 -> 0 | K21: 4673732410247 | M21: 4673732410254 | P21: =$P$8 -> 0 | R21: =IF(Q21>0,Q21,P21) -> 0 | S21: =IF(P21>18,"ПЕРЕБОР","-") -> - | T21: 69 | V21: 1.25 | W21: =T21*V21 -> 86.25 | X21: =R21*0.01 -> 0 | Y21: =W21-(W21*X21) -> 86.25 | Z21: =ROUND(Y21,2) -> 86.25 | AB21: 0.12 | AC21: =H21*AB21 -> 0 | AD21: =AC21*$P$7 -> 0 | AE21: =AB21*$P$7 -> 1.92 | AF21: =ROUND(AE21,2) -> 1.92 | AH21: =ROUNDUP(AN21,2) -> 86.25 | AJ21: =IF($V$4,AL21+AF21,AL21) -> 86.25 | AL21: =IF($V$5,Z21-Z21*10%,Z21) -> 86.25 | AN21: =IF($V$3,AJ21-((AJ21*1.18031)-AJ21),AJ21) -> 86.25
... B92: 402-010-22460 | C92: Бур по бетону SDS+ (22х460) | D92: 1 | E92: 25 | F92: 25 | G92: =AH92 -> 372.64 | I92: - | J92: =G92*H92 -> 0 | K92: 4673759127746 | M92: 4673759127753 | P92: =$P$8 -> 0 | R92: =IF(Q92>0,Q92,P92) -> 0 | S92: =IF(P92>18,"ПЕРЕБОР","-") -> - | T92: 298.11 | V92: 1.25 | W92: =T92*V92 -> 372.6375 | X92: =R92*0.01 -> 0 | Y92: =W92-(W92*X92) -> 372.6375 | Z92: =ROUND(Y92,2) -> 372.64 | AB92: 0.56 | AC92: =H92*AB92 -> 0 | AD92: =AC92*$P$7 -> 0 | AE92: =AB92*$P$7 -> 8.96 | AF92: =ROUND(AE92,2) -> 8.96 | AH92: =ROUNDUP(AN92,2) -> 372.64 | AJ92: =IF($V$4,AL92+AF92,AL92) -> 372.64 | AL92: =IF($V$5,Z92-Z92*10%,Z92) -> 372.64 | AN92: =IF($V$3,AJ92-((AJ92*1.18031)-AJ92),AJ92) -> 372.64
B93: Зубило SDS+ | O93: Зубило SDS+
B94: 411-010-1425020 | C94: Зубило SDS+ (14x250x20) | D94: 1 | E94: 10 | F94: 100 | G94: =AH94 -> 126.39 | I94: - | J94: =G94*H94 -> 0 | K94: 4673732410780 | M94: 4673732410797 | P94: =$P$8 -> 0 | R94: =IF(Q94>0,Q94,P94) -> 0 | S94: =IF(P94>18,"ПЕРЕБОР","-") -> - | T94: 101.112 | V94: 1.25 | W94: =T94*V94 -> 126.39 | X94: =R94*0.01 -> 0 | Y94: =W94-(W94*X94) -> 126.39 | Z94: =ROUND(Y94,2) -> 126.39 | AB94: 0.25 | AC94: =H94*AB94 -> 0 | AD94: =AC94*$P$7 -> 0 | AE94: =AB94*$P$7 -> 4 | AF94: =ROUND(AE94,2) -> 4 | AH94: =ROUNDUP(AN94,2) -> 126.39 | AJ94: =IF($V$4,AL94+AF94,AL94) -> 126.39 | AL94: =IF($V$5,Z94-Z94*10%,Z94) -> 126.39 | AN94: =IF($V$3,AJ94-((AJ94*1.18031)-AJ94),AJ94) -> 126.39
B95: 411-010-1425050 | C95: Зубило SDS+ (14x250x50) | D95: 1 | E95: 10 | F95: 100 | G95: =AH95 -> 183.48 | I95: - | J95: =G95*H95 -> 0 | K95: 4673732410803 | M95: 4673732410810 | P95: =$P$8 -> 0 | R95: =IF(Q95>0,Q95,P95) -> 0 | S95: =IF(P95>18,"ПЕРЕБОР","-") -> - | T95: 146.784 | V95: 1.25 | W95: =T95*V95 -> 183.48 | X95: =R95*0.01 -> 0 | Y95: =W95-(W95*X95) -> 183.48 | Z95: =ROUND(Y95,2) -> 183.48 | AB95: 0.29 | AC95: =H95*AB95 -> 0 | AD95: =AC95*$P$7 -> 0 | AE95: =AB95*$P$7 -> 4.64 | AF95: =ROUND(AE95,2) -> 4.64 | AH95: =ROUNDUP(AN95,2) -> 183.48 | AJ95: =IF($V$4,AL95+AF95,AL95) -> 183.48 | AL95: =IF($V$5,Z95-Z95*10%,Z95) -> 183.48 | AN95: =IF($V$3,AJ95-((AJ95*1.18031)-AJ95),AJ95) -> 183.48
B96: 411-010-1440020 | C96: Зубило SDS+ (14x400x20) | D96: 1 | E96: 10 | F96: 50 | G96: =AH96 -> 216.25 | I96: - | J96: =G96*H96 -> 0 | K96: 4673768180541 | M96: 4673768180558 | P96: =$P$8 -> 0 | R96: =IF(Q96>0,Q96,P96) -> 0 | S96: =IF(P96>18,"ПЕРЕБОР","-") -> - | T96: 173 | V96: 1.25 | W96: =T96*V96 -> 216.25 | X96: =R96*0.01 -> 0 | Y96: =W96-(W96*X96) -> 216.25 | Z96: =ROUND(Y96,2) -> 216.25 | AB96: 0.44 | AC96: =H96*AB96 -> 0 | AD96: =AC96*$P$7 -> 0 | AE96: =AB96*$P$7 -> 7.04 | AF96: =ROUND(AE96,2) -> 7.04 | AH96: =ROUNDUP(AN96,2) -> 216.25 | AJ96: =IF($V$4,AL96+AF96,AL96) -> 216.25 | AL96: =IF($V$5,Z96-Z96*10%,Z96) -> 216.25 | AN96: =IF($V$3,AJ96-((AJ96*1.18031)-AJ96),AJ96) -> 216.25
B97: 411-010-1440050 | C97: Зубило SDS+ (14x400x50) | D97: 1 | E97: 10 | F97: 50 | G97: =AH97 -> 287.56 | I97: - | J97: =G97*H97 -> 0 | K97: 4673768180565 | M97: 4673768180572 | P97: =$P$8 -> 0 | R97: =IF(Q97>0,Q97,P97) -> 0 | S97: =IF(P97>18,"ПЕРЕБОР","-") -> - | T97: 230.05 | V97: 1.25 | W97: =T97*V97 -> 287.5625 | X97: =R97*0.01 -> 0 | Y97: =W97-(W97*X97) -> 287.5625 | Z97: =ROUND(Y97,2) -> 287.56 | AB97: 0.5 | AC97: =H97*AB97 -> 0 | AD97: =AC97*$P$7 -> 0 | AE97: =AB97*$P$7 -> 8 | AF97: =ROUND(AE97,2) -> 8 | AH97: =ROUNDUP(AN97,2) -> 287.56 | AJ97: =IF($V$4,AL97+AF97,AL97) -> 287.56 | AL97: =IF($V$5,Z97-Z97*10%,Z97) -> 287.56 | AN97: =IF($V$3,AJ97-((AJ97*1.18031)-AJ97),AJ97) -> 287.56
B98: 411-010-1460020 | C98: Зубило SDS+ (14x600x20) | D98: 1 | E98: 5 | F98: 25 | G98: =AH98 -> 310.56 | I98: - | J98: =G98*H98 -> 0 | K98: 4673768180589 | M98: 4673768180596 | P98: =$P$8 -> 0 | R98: =IF(Q98>0,Q98,P98) -> 0 | S98: =IF(P98>18,"ПЕРЕБОР","-") -> - | T98: 248.45 | V98: 1.25 | W98: =T98*V98 -> 310.5625 | X98: =R98*0.01 -> 0 | Y98: =W98-(W98*X98) -> 310.5625 | Z98: =ROUND(Y98,2) -> 310.56 | AB98: 0.72 | AC98: =H98*AB98 -> 0 | AD98: =AC98*$P$7 -> 0 | AE98: =AB98*$P$7 -> 11.52 | AF98: =ROUND(AE98,2) -> 11.52 | AH98: =ROUNDUP(AN98,2) -> 310.56 | AJ98: =IF($V$4,AL98+AF98,AL98) -> 310.56 | AL98: =IF($V$5,Z98-Z98*10%,Z98) -> 310.56 | AN98: =IF($V$3,AJ98-((AJ98*1.18031)-AJ98),AJ98) -> 310.56
B99: 411-010-1460050 | C99: Зубило SDS+ (14x600x50) | D99: 1 | E99: 5 | F99: 25 | G99: =AH99 -> 411.9 | I99: - | J99: =G99*H99 -> 0 | K99: 4673768180602 | M99: 4673768180619 | P99: =$P$8 -> 0 | R99: =IF(Q99>0,Q99,P99) -> 0 | S99: =IF(P99>18,"ПЕРЕБОР","-") -> - | T99: 329.5215 | V99: 1.25 | W99: =T99*V99 -> 411.90188 | X99: =R99*0.01 -> 0 | Y99: =W99-(W99*X99) -> 411.90188 | Z99: =ROUND(Y99,2) -> 411.9 | AB99: 0.8 | AC99: =H99*AB99 -> 0 | AD99: =AC99*$P$7 -> 0 | AE99: =AB99*$P$7 -> 12.8 | AF99: =ROUND(AE99,2) -> 12.8 | AH99: =ROUNDUP(AN99,2) -> 411.9 | AJ99: =IF($V$4,AL99+AF99,AL99) -> 411.9 | AL99: =IF($V$5,Z99-Z99*10%,Z99) -> 411.9 | AN99: =IF($V$3,AJ99-((AJ99*1.18031)-AJ99),AJ99) -> 411.9
B100: Коронка по бетону SDS+ | O100: Коронка по бетону SDS+
B101: 422-010-30 | C101: Коронка по бетону SDS+ D30 | D101: 1 | E101: / | F101: 50 | G101: =AH101 -> 351.13 | I101: - | J101: =G101*H101 -> 0 | K101: 4673759127760 | M101: 4673759127777 | P101: =$P$8 -> 0 | R101: =IF(Q101>0,Q101,P101) -> 0 | S101: =IF(P101>18,"ПЕРЕБОР","-") -> - | T101: 280.9 | V101: 1.25 | W101: =T101*V101 -> 351.125 | X101: =R101*0.01 -> 0 | Y101: =W101-(W101*X101) -> 351.125 | Z101: =ROUND(Y101,2) -> 351.13 | AB101: 0.4 | AC101: =H101*AB101 -> 0 | AD101: =AC101*$P$7 -> 0 | AE101: =AB101*$P$7 -> 6.4 | AF101: =ROUND(AE101,2) -> 6.4 | AH101: =ROUNDUP(AN101,2) -> 351.13 | AJ101: =IF($V$4,AL101+AF101,AL101) -> 351.13 | AL101: =IF($V$5,Z101-Z101*10%,Z101) -> 351.13 | AN101: =IF($V$3,AJ101-((AJ101*1.18031)-AJ101),AJ101) -> 351.13
B102: 422-010-35 | C102: Коронка по бетону SDS+ D35 | D102: 1 | E102: / | F102: 50 | G102: =AH102 -> 364.48 | I102: - | J102: =G102*H102 -> 0 | K102: 4673759127784 | M102: 4673759127791 | P102: =$P$8 -> 0 | R102: =IF(Q102>0,Q102,P102) -> 0 | S102: =IF(P102>18,"ПЕРЕБОР","-") -> - | T102: 291.58 | V102: 1.25 | W102: =T102*V102 -> 364.475 | X102: =R102*0.01 -> 0 | Y102: =W102-(W102*X102) -> 364.475 | Z102: =ROUND(Y102,2) -> 364.48 | AB102: 0.42 | AC102: =H102*AB102 -> 0 | AD102: =AC102*$P$7 -> 0 | AE102: =AB102*$P$7 -> 6.72 | AF102: =ROUND(AE102,2) -> 6.72 | AH102: =ROUNDUP(AN102,2) -> 364.48 | AJ102: =IF($V$4,AL102+AF102,AL102) -> 364.48 | AL102: =IF($V$5,Z102-Z102*10%,Z102) -> 364.48 | AN102: =IF($V$3,AJ102-((AJ102*1.18031)-AJ102),AJ102) -> 364.48
B103: 422-010-40 | C103: Коронка по бетону SDS+ D40 | D103: 1 | E103: / | F103: 50 | G103: =AH103 -> 438.6 | I103: - | J103: =G103*H103 -> 0 | K103: 4673759127807 | M103: 4673759127814 | P103: =$P$8 -> 0 | R103: =IF(Q103>0,Q103,P103) -> 0 | S103: =IF(P103>18,"ПЕРЕБОР","-") -> - | T103: 350.88 | V103: 1.25 | W103: =T103*V103 -> 438.6 | X103: =R103*0.01 -> 0 | Y103: =W103-(W103*X103) -> 438.6 | Z103: =ROUND(Y103,2) -> 438.6 | AB103: 0.44 | AC103: =H103*AB103 -> 0 | AD103: =AC103*$P$7 -> 0 | AE103: =AB103*$P$7 -> 7.04 | AF103: =ROUND(AE103,2) -> 7.04 | AH103: =ROUNDUP(AN103,2) -> 438.6 | AJ103: =IF($V$4,AL103+AF103,AL103) -> 438.6 | AL103: =IF($V$5,Z103-Z103*10%,Z103) -> 438.6 | AN103: =IF($V$3,AJ103-((AJ103*1.18031)-AJ103),AJ103) -> 438.6
B104: 422-010-45 | C104: Коронка по бетону SDS+ D45 | D104: 1 | E104: / | F104: 50 | G104: =AH104 -> 547 | I104: - | J104: =G104*H104 -> 0 | K104: 4673732414535 | M104: 4673732414542 | P104: =$P$8 -> 0 | R104: =IF(Q104>0,Q104,P104) -> 0 | S104: =IF(P104>18,"ПЕРЕБОР","-") -> - | T104: 437.602 | V104: 1.25 | W104: =T104*V104 -> 547.0025 | X104: =R104*0.01 -> 0 | Y104: =W104-(W104*X104) -> 547.0025 | Z104: =ROUND(Y104,2) -> 547 | AB104: 0.49 | AC104: =H104*AB104 -> 0 | AD104: =AC104*$P$7 -> 0 | AE104: =AB104*$P$7 -> 7.84 | AF104: =ROUND(AE104,2) -> 7.84 | AH104: =ROUNDUP(AN104,2) -> 547 | AJ104: =IF($V$4,AL104+AF104,AL104) -> 547 | AL104: =IF($V$5,Z104-Z104*10%,Z104) -> 547 | AN104: =IF($V$3,AJ104-((AJ104*1.18031)-AJ104),AJ104) -> 547
B105: 422-010-50 | C105: Коронка по бетону SDS+ D50 | D105: 1 | E105: / | F105: 50 | G105: =AH105 -> 586.84 | I105: - | J105: =G105*H105 -> 0 | K105: 4673732414566 | M105: 4673732414559 | P105: =$P$8 -> 0 | R105: =IF(Q105>0,Q105,P105) -> 0 | S105: =IF(P105>18,"ПЕРЕБОР","-") -> - | T105: 469.475 | V105: 1.25 | W105: =T105*V105 -> 586.84375 | X105: =R105*0.01 -> 0 | Y105: =W105-(W105*X105) -> 586.84375 | Z105: =ROUND(Y105,2) -> 586.84 | AB105: 0.56 | AC105: =H105*AB105 -> 0 | AD105: =AC105*$P$7 -> 0 | AE105: =AB105*$P$7 -> 8.96 | AF105: =ROUND(AE105,2) -> 8.96 | AH105: =ROUNDUP(AN105,2) -> 586.84 | AJ105: =IF($V$4,AL105+AF105,AL105) -> 586.84 | AL105: =IF($V$5,Z105-Z105*10%,Z105) -> 586.84 | AN105: =IF($V$3,AJ105-((AJ105*1.18031)-AJ105),AJ105) -> 586.84
B106: 422-010-55 | C106: Коронка по бетону SDS+ D55 | D106: 1 | E106: / | F106: 20 | G106: =AH106 -> 481.84 | I106: - | J106: =G106*H106 -> 0 | K106: 4673732414597 | M106: 4673732414603 | P106: =$P$8 -> 0 | R106: =IF(Q106>0,Q106,P106) -> 0 | S106: =IF(P106>18,"ПЕРЕБОР","-") -> - | T106: 385.47 | V106: 1.25 | W106: =T106*V106 -> 481.8375 | X106: =R106*0.01 -> 0 | Y106: =W106-(W106*X106) -> 481.8375 | Z106: =ROUND(Y106,2) -> 481.84 | AB106: 0.6 | AC106: =H106*AB106 -> 0 | AD106: =AC106*$P$7 -> 0 | AE106: =AB106*$P$7 -> 9.6 | AF106: =ROUND(AE106,2) -> 9.6 | AH106: =ROUNDUP(AN106,2) -> 481.84 | AJ106: =IF($V$4,AL106+AF106,AL106) -> 481.84 | AL106: =IF($V$5,Z106-Z106*10%,Z106) -> 481.84 | AN106: =IF($V$3,AJ106-((AJ106*1.18031)-AJ106),AJ106) -> 481.84
B107: 422-010-60 | C107: Коронка по бетону SDS+ D60 | D107: 1 | E107: / | F107: 20 | G107: =AH107 -> 506.55 | I107: - | J107: =G107*H107 -> 0 | K107: 4673732414610 | M107: 4673732414627 | P107: =$P$8 -> 0 | R107: =IF(Q107>0,Q107,P107) -> 0 | S107: =IF(P107>18,"ПЕРЕБОР","-") -> - | T107: 405.24 | V107: 1.25 | W107: =T107*V107 -> 506.55 | X107: =R107*0.01 -> 0 | Y107: =W107-(W107*X107) -> 506.55 | Z107: =ROUND(Y107,2) -> 506.55 | AB107: 0.65 | AC107: =H107*AB107 -> 0 | AD107: =AC107*$P$7 -> 0 | AE107: =AB107*$P$7 -> 10.4 | AF107: =ROUND(AE107,2) -> 10.4 | AH107: =ROUNDUP(AN107,2) -> 506.55 | AJ107: =IF($V$4,AL107+AF107,AL107) -> 506.55 | AL107: =IF($V$5,Z107-Z107*10%,Z107) -> 506.55 | AN107: =IF($V$3,AJ107-((AJ107*1.18031)-AJ107),AJ107) -> 506.55
B108: 422-010-65 | C108: Коронка по бетону SDS+ D65 | D108: 1 | E108: / | F108: 20 | G108: =AH108 -> 647.19 | I108: - | J108: =G108*H108 -> 0 | K108: 4673732410827 | M108: 4673732410834 | P108: =$P$8 -> 0 | R108: =IF(Q108>0,Q108,P108) -> 0 | S108: =IF(P108>18,"ПЕРЕБОР","-") -> - | T108: 517.753 | V108: 1.25 | W108: =T108*V108 -> 647.19125 | X108: =R108*0.01 -> 0 | Y108: =W108-(W108*X108) -> 647.19125 | Z108: =ROUND(Y108,2) -> 647.19 | AB108: 0.8 | AC108: =H108*AB108 -> 0 | AD108: =AC108*$P$7 -> 0 | AE108: =AB108*$P$7 -> 12.8 | AF108: =ROUND(AE108,2) -> 12.8 | AH108: =ROUNDUP(AN108,2) -> 647.19 | AJ108: =IF($V$4,AL108+AF108,AL108) -> 647.19 | AL108: =IF($V$5,Z108-Z108*10%,Z108) -> 647.19 | AN108: =IF($V$3,AJ108-((AJ108*1.18031)-AJ108),AJ108) -> 647.19
B109: 422-010-68 | C109: Коронка по бетону SDS+ D68 | D109: 1 | E109: / | F109: 20 | G109: =AH109 -> 700.16 | I109: - | J109: =G109*H109 -> 0 | K109: 4673732410841 | M109: 4673732410858 | P109: =$P$8 -> 0 | R109: =IF(Q109>0,Q109,P109) -> 0 | S109: =IF(P109>18,"ПЕРЕБОР","-") -> - | T109: 560.1305 | V109: 1.25 | W109: =T109*V109 -> 700.16313 | X109: =R109*0.01 -> 0 | Y109: =W109-(W109*X109) -> 700.16313 | Z109: =ROUND(Y109,2) -> 700.16 | AB109: 0.85 | AC109: =H109*AB109 -> 0 | AD109: =AC109*$P$7 -> 0 | AE109: =AB109*$P$7 -> 13.6 | AF109: =ROUND(AE109,2) -> 13.6 | AH109: =ROUNDUP(AN109,2) -> 700.16 | AJ109: =IF($V$4,AL109+AF109,AL109) -> 700.16 | AL109: =IF($V$5,Z109-Z109*10%,Z109) -> 700.16 | AN109: =IF($V$3,AJ109-((AJ109*1.18031)-AJ109),AJ109) -> 700.16
B110: 422-010-70 | C110: Коронка по бетону SDS+ D70 | D110: 1 | E110: / | F110: 20 | G110: =AH110 -> 734.95 | I110: - | J110: =G110*H110 -> 0 | K110: 4673732410865 | M110: 4673732410872 | P110: =$P$8 -> 0 | R110: =IF(Q110>0,Q110,P110) -> 0 | S110: =IF(P110>18,"ПЕРЕБОР","-") -> - | T110: 587.961 | V110: 1.25 | W110: =T110*V110 -> 734.95125 | X110: =R110*0.01 -> 0 | Y110: =W110-(W110*X110) -> 734.95125 | Z110: =ROUND(Y110,2) -> 734.95 | AB110: 0.875 | AC110: =H110*AB110 -> 0 | AD110: =AC110*$P$7 -> 0 | AE110: =AB110*$P$7 -> 14 | AF110: =ROUND(AE110,2) -> 14 | AH110: =ROUNDUP(AN110,2) -> 734.95 | AJ110: =IF($V$4,AL110+AF110,AL110) -> 734.95 | AL110: =IF($V$5,Z110-Z110*10%,Z110) -> 734.95 | AN110: =IF($V$3,AJ110-((AJ110*1.18031)-AJ110),AJ110) -> 734.95
B111: 422-010-75 | C111: Коронка по бетону SDS+ D75 | D111: 1 | E111: / | F111: 20 | G111: =AH111 -> 630.09 | I111: - | J111: =G111*H111 -> 0 | K111: 4673732410889 | M111: 4673732410896 | P111: =$P$8 -> 0 | R111: =IF(Q111>0,Q111,P111) -> 0 | S111: =IF(P111>18,"ПЕРЕБОР","-") -> - | T111: 504.07 | V111: 1.25 | W111: =T111*V111 -> 630.0875 | X111: =R111*0.01 -> 0 | Y111: =W111-(W111*X111) -> 630.0875 | Z111: =ROUND(Y111,2) -> 630.09 | AB111: 0.925 | AC111: =H111*AB111 -> 0 | AD111: =AC111*$P$7 -> 0 | AE111: =AB111*$P$7 -> 14.8 | AF111: =ROUND(AE111,2) -> 14.8 | AH111: =ROUNDUP(AN111,2) -> 630.09 | AJ111: =IF($V$4,AL111+AF111,AL111) -> 630.09 | AL111: =IF($V$5,Z111-Z111*10%,Z111) -> 630.09 | AN111: =IF($V$3,AJ111-((AJ111*1.18031)-AJ111),AJ111) -> 630.09
B112: 422-010-100 | C112: Коронка по бетону SDS+ D100 | D112: 1 | E112: / | F112: 10 | G112: =AH112 -> 1114.4 | I112: - | J112: =G112*H112 -> 0 | K112: 4673732410902 | M112: 4673732410919 | P112: =$P$8 -> 0 | R112: =IF(Q112>0,Q112,P112) -> 0 | S112: =IF(P112>18,"ПЕРЕБОР","-") -> - | T112: 891.517 | V112: 1.25 | W112: =T112*V112 -> 1114.3963 | X112: =R112*0.01 -> 0 | Y112: =W112-(W112*X112) -> 1114.3963 | Z112: =ROUND(Y112,2) -> 1114.4 | AB112: 1.2 | AC112: =H112*AB112 -> 0 | AD112: =AC112*$P$7 -> 0 | AE112: =AB112*$P$7 -> 19.2 | AF112: =ROUND(AE112,2) -> 19.2 | AH112: =ROUNDUP(AN112,2) -> 1114.4 | AJ112: =IF($V$4,AL112+AF112,AL112) -> 1114.4 | AL112: =IF($V$5,Z112-Z112*10%,Z112) -> 1114.4 | AN112: =IF($V$3,AJ112-((AJ112*1.18031)-AJ112),AJ112) -> 1114.4
...

Sheet KRONbuild
D2: +7 (926) 489-69-85 (Москва) 8 (423) 200-02-26 (Владивосток) www.kronbuild.ru | G2: +7 (926) 489-69-85 (Москва) 8 (423) 200-02-26 (Владивосток) www.headrock.ru
A8: Сентябрь 2026 | J8: =I195 -> 0
A9: артикул | B9: изображение | C9: наименование | D9: вес (грамм) | E9: выход (литров) | F9: количество в коробке | G9: Цена в руб. (с НДС 22%): | H9: Ваш заказ (коробок) | I9: Ваш заказ (штук/комплектов) | J9: Сумма заказа в руб. (с НДС 20%) | L9: Штрихкод штуки | M9: Штрихкод коробки
C10: Профессиональная монтажная пена KRONbuild (пистолетная)
A11: FWPM80 | C11: Зима Masters 80 | D11: 1000 | E11: 80 | F11: 12 | G11: ='+'!AI11 -> 446.25 | I11: =H11*F11 -> 0 | J11: =G11*I11 -> 0 | L11: 4660447836226 | M11: 4673759127258
A12: FSPM80 | C12: Лето Masters 80 АКЦИЯ! | D12: 1000 | E12: 80 | F12: 12 | G12: ='+'!AI12 -> 383.75 | I12: =H12*F12 -> 0 | J12: =G12*I12 -> 0 | L12: 4660447836233 | M12: 4673759127272
A13: FSP70 | C13: Лето PRO 70 АКЦИЯ! | D13: 950 | E13: 70 | F13: 12 | G13: ='+'!AI13 -> 335 | I13: =H13*F13 -> 0 | J13: =G13*I13 -> 0 | L13: 4660447836295 | M13: 4627168565842
A14: FSU65 | C14: Лето Ultra 65 АКЦИЯ! | D14: 850 | E14: 65 | F14: 12 | G14: ='+'!AI14 -> 315 | I14: =H14*F14 -> 0 | J14: =G14*I14 -> 0 | L14: 4660447836301 | M14: 4627168562827
A15: FAS70 | C15: Всесезонная PRO 70 | D15: 950 | E15: 70 | F15: 12 | G15: ='+'!AI15 -> 396.25 | I15: =H15*F15 -> 0 | J15: =G15*I15 -> 0 | L15: 4660447836257 | M15: 4627198693171
A16: FAS65U | C16: Всесезонная Ultra 65 | D16: 850 | E16: 65 | F16: 12 | G16: ='+'!AI16 -> 353.75 | I16: =H16*F16 -> 0 | J16: =G16*I16 -> 0 | L16: 4660447836264 | M16: 4627168566122
A17: FWP70 | C17: Зима PRO 70 | D17: 950 | E17: 70 | F17: 12 | G17: ='+'!AI17 -> 392.5 | I17: =H17*F17 -> 0 | J17: =G17*I17 -> 0 | L17: 4660447836271 | M17: 14627147350046
A18: FWU65 | C18: Зима Ultra 65 | D18: 850 | E18: 65 | F18: 12 | G18: ='+'!AI18 -> 375 | I18: =H18*F18 -> 0 | J18: =G18*I18 -> 0 | L18: 4660447836288 | M18: 4627168562803
C19: Профессиональная общестроительная монтажная пена KRONbuild (пистолетная)
A20: FSS65 | C20: Лето Standart 65 АКЦИЯ! | D20: 800 | E20: 65 | F20: 12 | G20: ='+'!AI20 -> 292.5 | I20: =H20*F20 -> 0 | J20: =G20*I20 -> 0 | L20: 4660447836356 | M20: 4627168565866
A21: FASST | C21: Всесезонная Standart 65 | D21: 800 | E21: 65 | F21: 12 | G21: ='+'!AI21 -> 337.5 | I21: =H21*F21 -> 0 | J21: =G21*I21 -> 0 | L21: 4660447836332 | M21: 4673732414528
A22: FASGUN65 | C22: Всесезонная HANDGUN 65 | D22: 800 | E22: 65 | F22: 12 | G22: ='+'!AI22 -> 351.25 | I22: =H22*F22 -> 0 | J22: =G22*I22 -> 0 | L22: 4660447836240 | M22: 4673759127234
A23: FAO65 | C23: Всесезонная ONE 65 | D23: 770 | E23: 65 | F23: 12 | G23: ='+'!AI23 -> 293.75 | I23: =H23*F23 -> 0 | J23: =G23*I23 -> 0 | L23: 4660447836325 | M23: 4627198692020
A24: FAS650 | C24: Всесезонная 65 | D24: 650 | E24: 65 | F24: 12 | G24: ='+'!AI24 -> 270 | I24: =H24*F24 -> 0 | J24: =G24*I24 -> 0 | L24: 4660447836318 | M24: 4627198691986
A25: FWS65 | C25: Зима Standart 65 | D25: 800 | E25: 65 | F25: 12 | G25: ='+'!AI25 -> 352.5 | I25: =H25*F25 -> 0 | J25: =G25*I25 -> 0 | L25: 4660447836349 | M25: 14627147350039
C26: Профессиональная специальная монтажная пена KRONbuild (пистолетная)
A27: FPFB1 | C27: Огнестойкая B1 | D27: 850 | E27: 65 | F27: 12 | G27: ='+'!AI27 -> 475 | I27: =H27*F27 -> 0 | J27: =G27*I27 -> 0 | L27: 4660447836387 | M27: 4673732414252
A28: FC850 | C28: Цемент-пена | D28: 900 | E28: - | F28: 12 | G28: ='+'!AI28 -> 515 | I28: =H28*F28 -> 0 | J28: =G28*I28 -> 0 | L28: 4660447836394 | M28: 4673743522878
A29: PUI90 | C29: Напыляемый утеплитель + насадка-распылитель | D29: 900 | E29: - | F29: 12 | G29: ='+'!AI29 -> 555 | I29: =H29*F29 -> 0 | J29: =G29*I29 -> 0 | L29: 4660447836370 | M29: 4673732414917
A30: GF800 | C30: Клей-пена | D30: 800 | E30: 65 | F30: 12 | G30: ='+'!AI30 -> 398.75 | I30: =H30*F30 -> 0 | J30: =G30*I30 -> 0 | L30: 4660447836363 | M30: 4627198692006
C31: Бытовая монтажная пена KRONbuild
A32: FH200 | C32: Всесезонная 20+ | D32: 380 | E32: 20+ | F32: 12 | G32: ='+'!AI32 -> 176.25 | I32: =H32*F32 -> 0 | J32: =G32*I32 -> 0 | L32: 4660447836189 | M32: 14627155466425
A33: FH400 | C33: Всесезонная 40+ | D33: 500 | E33: 40+ | F33: 12 | G33: ='+'!AI33 -> 220 | I33: =H33*F33 -> 0 | J33: =G33*I33 -> 0 | L33: 4660447836196 | M33: 4627168566771
A34: FHO65 | C34: Всесезонная ONE 65 | D34: 770 | E34: 65 | F34: 12 | G34: ='+'!AI34 -> 293.75 | I34: =H34*F34 -> 0 | J34: =G34*I34 -> 0 | L34: 4660447836202 | M34: 4627181320091
C35: Очиститель монтажной пены KRONbuild
A36: CF351 | C36: Очиститель монтажной пены | D36: 350 | E36: - | F36: 12 | G36: ='+'!AI36 -> 140 | I36: =H36*F36 -> 0 | J36: =G36*I36 -> 0 | L36: 4627147350025 | M36: 14627147350022
C37: Герметики KRONbuild
A38: SUT80 | C38: Герметик универсальный (бесцветный) 80 мл | D38: 80 | E38: - | F38: 12 | G38: ='+'!AI38 -> 120 | I38: =H38*F38 -> 0 | J38: =G38*I38 -> 0 | L38: 4660447835984 | M38: 4673743524407
A39: SUW80 | C39: Герметик универсальный (белый) 80 мл | D39: 80 | E39: - | F39: 12 | G39: ='+'!AI39 -> 120 | I39: =H39*F39 -> 0 | J39: =G39*I39 -> 0 | L39: 4660447835960 | M39: 4673743524414
A40: SST80 | C40: Герметик санитарный (бесцветный) 80 мл | D40: 80 | E40: - | F40: 12 | G40: ='+'!AI40 -> 122.5 | I40: =H40*F40 -> 0 | J40: =G40*I40 -> 0 | L40: 4660447835946 | M40: 4673743524421
A41: SSW80 | C41: Герметик санитарный (белый) 80 мл | D41: 80 | E41: - | F41: 12 | G41: ='+'!AI41 -> 122.5 | I41: =H41*F41 -> 0 | J41: =G41*I41 -> 0 | L41: 4660447835922 | M41: 4673743524438
A42: SNT60 | C42: Герметик силиконовый нейтральный (бесцветный) 600 мл. | D42: 550 | E42: - | F42: 20 | G42: ='+'!AI42 -> 298.75 | I42: =H42*F42 -> 0 | J42: =G42*I42 -> 0 | L42: 4660447835908 | M42: 4673743522335
A43: SNW28 | C43: Герметик нейтральный (белый) 280 мл. | D43: 430 | E43: - | F43: 24 | G43: ='+'!AI43 -> 147.5 | I43: =H43*F43 -> 0 | J43: =G43*I43 -> 0 | L43: 4660447835885 | M43: 14627147356161
A44: SNT28 | C44: Герметик нейтральный (бесцветный) 280 мл. | D44: 300 | E44: - | F44: 24 | G44: ='+'!AI44 -> 150 | I44: =H44*F44 -> 0 | J44: =G44*I44 -> 0 | L44: 4660447835892 | M44: 4627168563428
A45: SSW28 | C45: Герметик санитарный (белый) 280 мл. | D45: 300 | E45: - | F45: 24 | G45: ='+'!AI45 -> 131.25 | I45: =H45*F45 -> 0 | J45: =G45*I45 -> 0 | L45: 4660447835915 | M45: 14627155469785
A46: SST28 | C46: Герметик санитарный (бесцветный) 280 мл. | D46: 300 | E46: - | F46: 24 | G46: ='+'!AI46 -> 131.25 | I46: =H46*F46 -> 0 | J46: =G46*I46 -> 0 | L46: 4660447835939 | M46: 4627168563442
...

Sheet +
O3: Корректировка 03 Сентябрь | AD3: FALSE | AE3: Включить стоимость доставки в цену
AD4: FALSE | AE4: Оплата за наличные
AD5: FALSE | AE5: Заграничный клиент, минус НДС
O6: КУБ УПЛОТН | P6: 5500
O7: ПО РФ | P7: 23 | AM7: 5
A8: Сентябрь 2026 | J8: =I195 -> 0 | T8: расчёт | AA8: Вес | AM8: %
A9: артикул | B9: изображение | C9: наименование | D9: вес (грамм) | E9: выход (литров) | F9: количество в коробке | G9: Цена в руб. (с НДС 20%): | H9: Ваш заказ (коробок) | I9: Ваш заказ (штук/комплектов) | J9: Сумма заказа в руб. (с НДС 20%) | L9: Штрихкод штуки | M9: Штрихкод коробки | O9: Скидка | P9: 0 | R9: min для ручного ввода | T9: коэфф max | U9: цена без скидки | V9: коэфф % | W9: без округления | X9: с округлением | AA9: Брутто коробки | AB9: Итого, кг. | AC9: Стоимость доставки | AD9: Вес штуки | AE9: округление до 3х знаков | AF9: Стоимость доставки за шт. руб. | AG9: округление до 2х знаков | AI9: Округление до 2х знаков | AK9: Если включить доставку в стоимость | AM9: Если оплата за наличку | AO9: Если заграничный клиент (-НДС) | AQ9: Рекомендованная цена Мин Кайрос
C10: Профессиональная монтажная пена KRONbuild (пистолетная) | O10: Проф.пена | Q10: =IF(P10>18,"ПЕРЕБОР","-") -> -
A11: FWPM80 | C11: Зима Masters 80 | D11: 1000 | E11: 80 | F11: 12 | G11: =AI11 -> 446.25 | I11: =H11*F11 -> 0 | J11: =G11*I11 -> 0 | L11: 4660447836226 | M11: 4673759127258 | P11: =$P$9 -> 0 | Q11: =IF(P11>18,"ПЕРЕБОР","-") -> - | R11: 357 | T11: 1.25 | U11: =R11*T11 -> 446.25 | V11: =P11*0.01 -> 0 | W11: =U11-(U11*V11) -> 446.25 | X11: =ROUND(W11,2) -> 446.25 | AA11: 12.3 | AB11: =H11*AA11 -> 0 | AC11: =AB11*$P$7 -> 0 | AD11: =AA11/F11 -> 1.025 | AE11: =ROUND(AD11,3) -> 1.025 | AF11: =AE11*$P$7 -> 23.575 | AG11: =ROUND(AF11,2) -> 23.58 | AI11: =ROUND(AO11,2) -> 446.25 | AK11: =IF($AD$3,AM11+AG11,AM11) -> 446.25 | AM11: =IF($AD$4,X11-($AM$7/100*X11),X11) -> 446.25 | AO11: =IF($AD$5,AK11-((AK11*1.18031)-AK11),AK11) -> 446.25
A12: FSPM80 | C12: Лето Masters 80 АКЦИЯ! | D12: 1000 | E12: 80 | F12: 12 | G12: =AI12 -> 383.75 | I12: =H12*F12 -> 0 | J12: =G12*I12 -> 0 | L12: 4660447836233 | M12: 4673759127272 | P12: =$P$9 -> 0 | Q12: =IF(P12>18,"ПЕРЕБОР","-") -> - | R12: 307 | T12: 1.25 | U12: =R12*T12 -> 383.75 | V12: =P12*0.01 -> 0 | W12: =U12-(U12*V12) -> 383.75 | X12: =ROUND(W12,2) -> 383.75 | AA12: 12.3 | AB12: =H12*AA12 -> 0 | AC12: =AB12*$P$7 -> 0 | AD12: =AA12/F12 -> 1.025 | AE12: =ROUND(AD12,3) -> 1.025 | AF12: =AE12*$P$7 -> 23.575 | AG12: =ROUND(AF12,2) -> 23.58 | AI12: =ROUND(AO12,2) -> 383.75 | AK12: =IF($AD$3,AM12+AG12,AM12) -> 383.75 | AM12: =IF($AD$4,X12-($AM$7/100*X12),X12) -> 383.75 | AO12: =IF($AD$5,AK12-((AK12*1.18031)-AK12),AK12) -> 383.75
A13: FSP70 | C13: Лето PRO 70 АКЦИЯ! | D13: 950 | E13: 70 | F13: 12 | G13: =AI13 -> 335 | I13: =H13*F13 -> 0 | J13: =G13*I13 -> 0 | L13: 4660447836295 | M13: 4627168565842 | P13: =$P$9 -> 0 | Q13: =IF(P13>18,"ПЕРЕБОР","-") -> - | R13: 268 | T13: 1.25 | U13: =R13*T13 -> 335 | V13: =P13*0.01 -> 0 | W13: =U13-(U13*V13) -> 335 | X13: =ROUND(W13,2) -> 335 | AA13: 11.8 | AB13: =H13*AA13 -> 0 | AC13: =AB13*$P$7 -> 0 | AD13: =AA13/F13 -> 0.98333333 | AE13: =ROUND(AD13,3) -> 0.983 | AF13: =AE13*$P$7 -> 22.609 | AG13: =ROUND(AF13,2) -> 22.61 | AI13: =ROUND(AO13,2) -> 335 | AK13: =IF($AD$3,AM13+AG13,AM13) -> 335 | AM13: =IF($AD$4,X13-($AM$7/100*X13),X13) -> 335 | AO13: =IF($AD$5,AK13-((AK13*1.18031)-AK13),AK13) -> 335
A14: FSU65 | C14: Лето Ultra 65 АКЦИЯ! | D14: 850 | E14: 65 | F14: 12 | G14: =AI14 -> 315 | I14: =H14*F14 -> 0 | J14: =G14*I14 -> 0 | L14: 4660447836301 | M14: 4627168562827 | P14: =$P$9 -> 0 | Q14: =IF(P14>18,"ПЕРЕБОР","-") -> - | R14: 252 | T14: 1.25 | U14: =R14*T14 -> 315 | V14: =P14*0.01 -> 0 | W14: =U14-(U14*V14) -> 315 | X14: =ROUND(W14,2) -> 315 | AA14: 10.6 | AB14: =H14*AA14 -> 0 | AC14: =AB14*$P$7 -> 0 | AD14: =AA14/F14 -> 0.88333333 | AE14: =ROUND(AD14,3) -> 0.883 | AF14: =AE14*$P$7 -> 20.309 | AG14: =ROUND(AF14,2) -> 20.31 | AI14: =ROUND(AO14,2) -> 315 | AK14: =IF($AD$3,AM14+AG14,AM14) -> 315 | AM14: =IF($AD$4,X14-($AM$7/100*X14),X14) -> 315 | AO14: =IF($AD$5,AK14-((AK14*1.18031)-AK14),AK14) -> 315
A15: FAS70 | C15: Всесезонная PRO 70 | D15: 950 | E15: 70 | F15: 12 | G15: =AI15 -> 396.25 | I15: =H15*F15 -> 0 | J15: =G15*I15 -> 0 | L15: 4660447836257 | M15: 4627198693171 | P15: =$P$9 -> 0 | Q15: =IF(P15>18,"ПЕРЕБОР","-") -> - | R15: 317 | T15: 1.25 | U15: =R15*T15 -> 396.25 | V15: =P15*0.01 -> 0 | W15: =U15-(U15*V15) -> 396.25 | X15: =ROUND(W15,2) -> 396.25 | AA15: 11.8 | AB15: =H15*AA15 -> 0 | AC15: =AB15*$P$7 -> 0 | AD15: =AA15/F15 -> 0.98333333 | AE15: =ROUND(AD15,3) -> 0.983 | AF15: =AE15*$P$7 -> 22.609 | AG15: =ROUND(AF15,2) -> 22.61 | AI15: =ROUND(AO15,2) -> 396.25 | AK15: =IF($AD$3,AM15+AG15,AM15) -> 396.25 | AM15: =IF($AD$4,X15-($AM$7/100*X15),X15) -> 396.25 | AO15: =IF($AD$5,AK15-((AK15*1.18031)-AK15),AK15) -> 396.25
A16: FAS65U | C16: Всесезонная Ultra 65 | D16: 850 | E16: 65 | F16: 12 | G16: =AI16 -> 353.75 | I16: =H16*F16 -> 0 | J16: =G16*I16 -> 0 | L16: 4660447836264 | M16: 4627168566122 | P16: =$P$9 -> 0 | R16: 283 | T16: 1.25 | U16: =R16*T16 -> 353.75 | V16: =P16*0.01 -> 0 | W16: =U16-(U16*V16) -> 353.75 | X16: =ROUND(W16,2) -> 353.75 | AA16: 10.6 | AB16: =H16*AA16 -> 0 | AC16: =AB16*$P$7 -> 0 | AD16: =AA16/F16 -> 0.88333333 | AE16: =ROUND(AD16,3) -> 0.883 | AF16: =AE16*$P$7 -> 20.309 | AG16: =ROUND(AF16,2) -> 20.31 | AI16: =ROUND(AO16,2) -> 353.75 | AK16: =IF($AD$3,AM16+AG16,AM16) -> 353.75 | AM16: =IF($AD$4,X16-($AM$7/100*X16),X16) -> 353.75 | AO16: =IF($AD$5,AK16-((AK16*1.18031)-AK16),AK16) -> 353.75
A17: FWP70 | C17: Зима PRO 70 | D17: 950 | E17: 70 | F17: 12 | G17: =AI17 -> 392.5 | I17: =H17*F17 -> 0 | J17: =G17*I17 -> 0 | L17: 4660447836271 | M17: 14627147350046 | P17: =$P$9 -> 0 | Q17: =IF(P17>18,"ПЕРЕБОР","-") -> - | R17: 314 | T17: 1.25 | U17: =R17*T17 -> 392.5 | V17: =P17*0.01 -> 0 | W17: =U17-(U17*V17) -> 392.5 | X17: =ROUND(W17,2) -> 392.5 | AA17: 11.8 | AB17: =H17*AA17 -> 0 | AC17: =AB17*$P$7 -> 0 | AD17: =AA17/F17 -> 0.98333333 | AE17: =ROUND(AD17,3) -> 0.983 | AF17: =AE17*$P$7 -> 22.609 | AG17: =ROUND(AF17,2) -> 22.61 | AI17: =ROUND(AO17,2) -> 392.5 | AK17: =IF($AD$3,AM17+AG17,AM17) -> 392.5 | AM17: =IF($AD$4,X17-($AM$7/100*X17),X17) -> 392.5 | AO17: =IF($AD$5,AK17-((AK17*1.18031)-AK17),AK17) -> 392.5
A18: FWU65 | C18: Зима Ultra 65 | D18: 850 | E18: 65 | F18: 12 | G18: =AI18 -> 375 | I18: =H18*F18 -> 0 | J18: =G18*I18 -> 0 | L18: 4660447836288 | M18: 4627168562803 | P18: =$P$9 -> 0 | Q18: =IF(P18>18,"ПЕРЕБОР","-") -> - | R18: 300 | T18: 1.25 | U18: =R18*T18 -> 375 | V18: =P18*0.01 -> 0 | W18: =U18-(U18*V18) -> 375 | X18: =ROUND(W18,2) -> 375 | AA18: 10.6 | AB18: =H18*AA18 -> 0 | AC18: =AB18*$P$7 -> 0 | AD18: =AA18/F18 -> 0.88333333 | AE18: =ROUND(AD18,3) -> 0.883 | AF18: =AE18*$P$7 -> 20.309 | AG18: =ROUND(AF18,2) -> 20.31 | AI18: =ROUND(AO18,2) -> 375 | AK18: =IF($AD$3,AM18+AG18,AM18) -> 375 | AM18: =IF($AD$4,X18-($AM$7/100*X18),X18) -> 375 | AO18: =IF($AD$5,AK18-((AK18*1.18031)-AK18),AK18) -> 375
C19: Профессиональная общестроительная монтажная пена KRONbuild (пистолетная) | O19: Общестроительная пена | Q19: =IF(P19>18,"ПЕРЕБОР","-") -> -
A20: FSS65 | C20: Лето Standart 65 АКЦИЯ! | D20: 800 | E20: 65 | F20: 12 | G20: =AI20 -> 292.5 | I20: =H20*F20 -> 0 | J20: =G20*I20 -> 0 | L20: 4660447836356 | M20: 4627168565866 | P20: =$P$9 -> 0 | Q20: =IF(P20>18,"ПЕРЕБОР","-") -> - | R20: 234 | T20: 1.25 | U20: =R20*T20 -> 292.5 | V20: =P20*0.01 -> 0 | W20: =U20-(U20*V20) -> 292.5 | X20: =ROUND(W20,2) -> 292.5 | AA20: 10 | AB20: =H20*AA20 -> 0 | AC20: =AB20*$P$7 -> 0 | AD20: =AA20/F20 -> 0.83333333 | AE20: =ROUND(AD20,3) -> 0.833 | AF20: =AE20*$P$7 -> 19.159 | AG20: =ROUND(AF20,2) -> 19.16 | AI20: =ROUND(AO20,2) -> 292.5 | AK20: =IF($AD$3,AM20+AG20,AM20) -> 292.5 | AM20: =IF($AD$4,X20-($AM$7/100*X20),X20) -> 292.5 | AO20: =IF($AD$5,AK20-((AK20*1.18031)-AK20),AK20) -> 292.5
A21: FASST | C21: Всесезонная Standart 65 | D21: 800 | E21: 65 | F21: 12 | G21: =AI21 -> 337.5 | I21: =H21*F21 -> 0 | J21: =G21*I21 -> 0 | L21: 4660447836332 | M21: 4673732414528 | P21: =$P$9 -> 0 | Q21: =IF(P21>18,"ПЕРЕБОР","-") -> - | R21: 270 | T21: 1.25 | U21: =R21*T21 -> 337.5 | V21: =P21*0.01 -> 0 | W21: =U21-(U21*V21) -> 337.5 | X21: =ROUND(W21,2) -> 337.5 | AA21: 10 | AB21: =H21*AA21 -> 0 | AC21: =AB21*$P$7 -> 0 | AD21: =AA21/F21 -> 0.83333333 | AE21: =ROUND(AD21,3) -> 0.833 | AF21: =AE21*$P$7 -> 19.159 | AG21: =ROUND(AF21,2) -> 19.16 | AI21: =ROUND(AO21,2) -> 337.5 | AK21: =IF($AD$3,AM21+AG21,AM21) -> 337.5 | AM21: =IF($AD$4,X21-($AM$7/100*X21),X21) -> 337.5 | AO21: =IF($AD$5,AK21-((AK21*1.18031)-AK21),AK21) -> 337.5
A22: FASGUN65 | C22: Всесезонная HANDGUN 65 | D22: 800 | E22: 65 | F22: 12 | G22: =AI22 -> 351.25 | I22: =H22*F22 -> 0 | J22: =G22*I22 -> 0 | L22: 4660447836240 | M22: 4673759127234 | P22: =$P$9 -> 0 | R22: 281 | T22: 1.25 | U22: =R22*T22 -> 351.25 | V22: =P22*0.01 -> 0 | W22: =U22-(U22*V22) -> 351.25 | X22: =ROUND(W22,2) -> 351.25 | AA22: 10 | AB22: =H22*AA22 -> 0 | AC22: =AB22*$P$7 -> 0 | AD22: =AA22/F22 -> 0.83333333 | AE22: =ROUND(AD22,3) -> 0.833 | AF22: =AE22*$P$7 -> 19.159 | AG22: =ROUND(AF22,2) -> 19.16 | AI22: =ROUND(AO22,2) -> 351.25 | AK22: =IF($AD$3,AM22+AG22,AM22) -> 351.25 | AM22: =IF($AD$4,X22-($AM$7/100*X22),X22) -> 351.25 | AO22: =IF($AD$5,AK22-((AK22*1.18031)-AK22),AK22) -> 351.25
A23: FAO65 | C23: Всесезонная ONE 65 | D23: 770 | E23: 65 | F23: 12 | G23: =AI23 -> 293.75 | I23: =H23*F23 -> 0 | J23: =G23*I23 -> 0 | L23: 4660447836325 | M23: 4627198692020 | P23: =$P$9 -> 0 | Q23: =IF(P23>18,"ПЕРЕБОР","-") -> - | R23: 235 | T23: 1.25 | U23: =R23*T23 -> 293.75 | V23: =P23*0.01 -> 0 | W23: =U23-(U23*V23) -> 293.75 | X23: =ROUND(W23,2) -> 293.75 | AA23: 9.64 | AB23: =H23*AA23 -> 0 | AC23: =AB23*$P$7 -> 0 | AD23: =AA23/F23 -> 0.80333333 | AE23: =ROUND(AD23,3) -> 0.803 | AF23: =AE23*$P$7 -> 18.469 | AG23: =ROUND(AF23,2) -> 18.47 | AI23: =ROUND(AO23,2) -> 293.75 | AK23: =IF($AD$3,AM23+AG23,AM23) -> 293.75 | AM23: =IF($AD$4,X23-($AM$7/100*X23),X23) -> 293.75 | AO23: =IF($AD$5,AK23-((AK23*1.18031)-AK23),AK23) -> 293.75
A24: FAS650 | C24: Всесезонная 65 | D24: 650 | E24: 65 | F24: 12 | G24: =AI24 -> 270 | I24: =H24*F24 -> 0 | J24: =G24*I24 -> 0 | L24: 4660447836318 | M24: 4627198691986 | P24: =$P$9 -> 0 | R24: 216 | T24: 1.25 | U24: =R24*T24 -> 270 | V24: =P24*0.01 -> 0 | W24: =U24-(U24*V24) -> 270 | X24: =ROUND(W24,2) -> 270 | AA24: 8.2 | AB24: =H24*AA24 -> 0 | AC24: =AB24*$P$7 -> 0 | AD24: =AA24/F24 -> 0.68333333 | AE24: =ROUND(AD24,3) -> 0.683 | AF24: =AE24*$P$7 -> 15.709 | AG24: =ROUND(AF24,2) -> 15.71 | AI24: =ROUND(AO24,2) -> 270 | AK24: =IF($AD$3,AM24+AG24,AM24) -> 270 | AM24: =IF($AD$4,X24-($AM$7/100*X24),X24) -> 270 | AO24: =IF($AD$5,AK24-((AK24*1.18031)-AK24),AK24) -> 270
A25: FWS65 | C25: Зима Standart 65 | D25: 800 | E25: 65 | F25: 12 | G25: =AI25 -> 352.5 | I25: =H25*F25 -> 0 | J25: =G25*I25 -> 0 | L25: 4660447836349 | M25: 14627147350039 | P25: =$P$9 -> 0 | Q25: =IF(P25>18,"ПЕРЕБОР","-") -> - | R25: 282 | T25: 1.25 | U25: =R25*T25 -> 352.5 | V25: =P25*0.01 -> 0 | W25: =U25-(U25*V25) -> 352.5 | X25: =ROUND(W25,2) -> 352.5 | AA25: 10 | AB25: =H25*AA25 -> 0 | AC25: =AB25*$P$7 -> 0 | AD25: =AA25/F25 -> 0.83333333 | AE25: =ROUND(AD25,3) -> 0.833 | AF25: =AE25*$P$7 -> 19.159 | AG25: =ROUND(AF25,2) -> 19.16 | AI25: =ROUND(AO25,2) -> 352.5 | AK25: =IF($AD$3,AM25+AG25,AM25) -> 352.5 | AM25: =IF($AD$4,X25-($AM$7/100*X25),X25) -> 352.5 | AO25: =IF($AD$5,AK25-((AK25*1.18031)-AK25),AK25) -> 352.5
C26: Профессиональная специальная монтажная пена KRONbuild (пистолетная) | O26: Специальная пена | Q26: =IF(P26>18,"ПЕРЕБОР","-") -> -
A27: FPFB1 | C27: Огнестойкая B1 | D27: 850 | E27: 65 | F27: 12 | G27: =AI27 -> 475 | I27: =H27*F27 -> 0 | J27: =G27*I27 -> 0 | L27: 4660447836387 | M27: 4673732414252 | P27: =$P$9 -> 0 | Q27: =IF(P27>18,"ПЕРЕБОР","-") -> - | R27: 380 | T27: 1.25 | U27: =R27*T27 -> 475 | V27: =P27*0.01 -> 0 | W27: =U27-(U27*V27) -> 475 | X27: =ROUND(W27,2) -> 475 | AA27: 10.6 | AB27: =H27*AA27 -> 0 | AC27: =AB27*$P$7 -> 0 | AD27: =AA27/F27 -> 0.88333333 | AE27: =ROUND(AD27,3) -> 0.883 | AF27: =AE27*$P$7 -> 20.309 | AG27: =ROUND(AF27,2) -> 20.31 | AI27: =ROUND(AO27,2) -> 475 | AK27: =IF($AD$3,AM27+AG27,AM27) -> 475 | AM27: =IF($AD$4,X27-($AM$7/100*X27),X27) -> 475 | AO27: =IF($AD$5,AK27-((AK27*1.18031)-AK27),AK27) -> 475
A28: FC850 | C28: Цемент-пена | D28: 900 | E28: - | F28: 12 | G28: =AI28 -> 515 | I28: =H28*F28 -> 0 | J28: =G28*I28 -> 0 | L28: 4660447836394 | M28: 4673743522878 | P28: =$P$9 -> 0 | Q28: =IF(P28>18,"ПЕРЕБОР","-") -> - | R28: 412 | T28: 1.25 | U28: =R28*T28 -> 515 | V28: =P28*0.01 -> 0 | W28: =U28-(U28*V28) -> 515 | X28: =ROUND(W28,2) -> 515 | AA28: 11.2 | AB28: =H28*AA28 -> 0 | AC28: =AB28*$P$7 -> 0 | AD28: =AA28/F28 -> 0.93333333 | AE28: =ROUND(AD28,3) -> 0.933 | AF28: =AE28*$P$7 -> 21.459 | AG28: =ROUND(AF28,2) -> 21.46 | AI28: =ROUND(AO28,2) -> 515 | AK28: =IF($AD$3,AM28+AG28,AM28) -> 515 | AM28: =IF($AD$4,X28-($AM$7/100*X28),X28) -> 515 | AO28: =IF($AD$5,AK28-((AK28*1.18031)-AK28),AK28) -> 515
A29: PUI90 | C29: Напыляемый утеплитель + насадка-распылитель | D29: 900 | E29: - | F29: 12 | G29: =AI29 -> 555 | I29: =H29*F29 -> 0 | J29: =G29*I29 -> 0 | L29: 4660447836370 | M29: 4673732414917 | P29: =$P$9 -> 0 | Q29: =IF(P29>18,"ПЕРЕБОР","-") -> - | R29: 444 | T29: 1.25 | U29: =R29*T29 -> 555 | V29: =P29*0.01 -> 0 | W29: =U29-(U29*V29) -> 555 | X29: =ROUND(W29,2) -> 555 | AA29: 11.2 | AB29: =H29*AA29 -> 0 | AC29: =AB29*$P$7 -> 0 | AD29: =AA29/F29 -> 0.93333333 | AE29: =ROUND(AD29,3) -> 0.933 | AF29: =AE29*$P$7 -> 21.459 | AG29: =ROUND(AF29,2) -> 21.46 | AI29: =ROUND(AO29,2) -> 555 | AK29: =IF($AD$3,AM29+AG29,AM29) -> 555 | AM29: =IF($AD$4,X29-($AM$7/100*X29),X29) -> 555 | AO29: =IF($AD$5,AK29-((AK29*1.18031)-AK29),AK29) -> 555
A30: GF800 | C30: Клей-пена | D30: 800 | E30: 65 | F30: 12 | G30: =AI30 -> 398.75 | I30: =H30*F30 -> 0 | J30: =G30*I30 -> 0 | L30: 4660447836363 | M30: 4627198692006 | P30: =$P$9 -> 0 | Q30: =IF(P30>18,"ПЕРЕБОР","-") -> - | R30: 319 | T30: 1.25 | U30: =R30*T30 -> 398.75 | V30: =P30*0.01 -> 0 | W30: =U30-(U30*V30) -> 398.75 | X30: =ROUND(W30,2) -> 398.75 | AA30: 10 | AB30: =H30*AA30 -> 0 | AC30: =AB30*$P$7 -> 0 | AD30: =AA30/F30 -> 0.83333333 | AE30: =ROUND(AD30,3) -> 0.833 | AF30: =AE30*$P$7 -> 19.159 | AG30: =ROUND(AF30,2) -> 19.16 | AI30: =ROUND(AO30,2) -> 398.75 | AK30: =IF($AD$3,AM30+AG30,AM30) -> 398.75 | AM30: =IF($AD$4,X30-($AM$7/100*X30),X30) -> 398.75 | AO30: =IF($AD$5,AK30-((AK30*1.18031)-AK30),AK30) -> 398.75
C31: Бытовая монтажная пена KRONbuild | O31: Бытовая пена | Q31: =IF(P31>18,"ПЕРЕБОР","-") -> -
A32: FH200 | C32: Всесезонная 20+ | D32: 380 | E32: 20+ | F32: 12 | G32: =AI32 -> 176.25 | I32: =H32*F32 -> 0 | J32: =G32*I32 -> 0 | L32: 4660447836189 | M32: 14627155466425 | P32: =$P$9 -> 0 | Q32: =IF(P32>18,"ПЕРЕБОР","-") -> - | R32: 141 | T32: 1.25 | U32: =R32*T32 -> 176.25 | V32: =P32*0.01 -> 0 | W32: =U32-(U32*V32) -> 176.25 | X32: =ROUND(W32,2) -> 176.25 | AA32: 5.2 | AB32: =H32*AA32 -> 0 | AC32: =AB32*$P$7 -> 0 | AD32: =AA32/F32 -> 0.43333333 | AE32: =ROUND(AD32,3) -> 0.433 | AF32: =AE32*$P$7 -> 9.959 | AG32: =ROUND(AF32,2) -> 9.96 | AI32: =ROUND(AO32,2) -> 176.25 | AK32: =IF($AD$3,AM32+AG32,AM32) -> 176.25 | AM32: =IF($AD$4,X32-($AM$7/100*X32),X32) -> 176.25 | AO32: =IF($AD$5,AK32-((AK32*1.18031)-AK32),AK32) -> 176.25
A33: FH400 | C33: Всесезонная 40+ | D33: 500 | E33: 40+ | F33: 12 | G33: =AI33 -> 220 | I33: =H33*F33 -> 0 | J33: =G33*I33 -> 0 | L33: 4660447836196 | M33: 4627168566771 | P33: =$P$9 -> 0 | Q33: =IF(P33>18,"ПЕРЕБОР","-") -> - | R33: 176 | T33: 1.25 | U33: =R33*T33 -> 220 | V33: =P33*0.01 -> 0 | W33: =U33-(U33*V33) -> 220 | X33: =ROUND(W33,2) -> 220 | AA33: 7.6 | AB33: =H33*AA33 -> 0 | AC33: =AB33*$P$7 -> 0 | AD33: =AA33/F33 -> 0.63333333 | AE33: =ROUND(AD33,3) -> 0.633 | AF33: =AE33*$P$7 -> 14.559 | AG33: =ROUND(AF33,2) -> 14.56 | AI33: =ROUND(AO33,2) -> 220 | AK33: =IF($AD$3,AM33+AG33,AM33) -> 220 | AM33: =IF($AD$4,X33-($AM$7/100*X33),X33) -> 220 | AO33: =IF($AD$5,AK33-((AK33*1.18031)-AK33),AK33) -> 220
A34: FHO65 | C34: Всесезонная ONE 65 | D34: 770 | E34: 65 | F34: 12 | G34: =AI34 -> 293.75 | I34: =H34*F34 -> 0 | J34: =G34*I34 -> 0 | L34: 4660447836202 | M34: 4627181320091 | P34: =$P$9 -> 0 | Q34: =IF(P34>18,"ПЕРЕБОР","-") -> - | R34: 235 | T34: 1.25 | U34: =R34*T34 -> 293.75 | V34: =P34*0.01 -> 0 | W34: =U34-(U34*V34) -> 293.75 | X34: =ROUND(W34,2) -> 293.75 | AA34: 9.64 | AB34: =H34*AA34 -> 0 | AC34: =AB34*$P$7 -> 0 | AD34: =AA34/F34 -> 0.80333333 | AE34: =ROUND(AD34,3) -> 0.803 | AF34: =AE34*$P$7 -> 18.469 | AG34: =ROUND(AF34,2) -> 18.47 | AI34: =ROUND(AO34,2) -> 293.75 | AK34: =IF($AD$3,AM34+AG34,AM34) -> 293.75 | AM34: =IF($AD$4,X34-($AM$7/100*X34),X34) -> 293.75 | AO34: =IF($AD$5,AK34-((AK34*1.18031)-AK34),AK34) -> 293.75
C35: Очиститель монтажной пены KRONbuild | O35: Очиститель м. пены | Q35: =IF(P35>18,"ПЕРЕБОР","-") -> - | AO35: =IF($AD$5,AK35-((AK35*1.18031)-AK35),AK35) -> 0
A36: CF351 | C36: Очиститель монтажной пены | D36: 350 | E36: - | F36: 12 | G36: =AI36 -> 140 | I36: =H36*F36 -> 0 | J36: =G36*I36 -> 0 | L36: 4627147350025 | M36: 14627147350022 | P36: =$P$9 -> 0 | Q36: =IF(P36>18,"ПЕРЕБОР","-") -> - | R36: 112 | T36: 1.25 | U36: =R36*T36 -> 140 | V36: =P36*0.01 -> 0 | W36: =U36-(U36*V36) -> 140 | X36: =ROUND(W36,2) -> 140 | AA36: 4.55 | AB36: =H36*AA36 -> 0 | AC36: =AB36*$P$7 -> 0 | AD36: =AA36/F36 -> 0.37916667 | AE36: =ROUND(AD36,3) -> 0.379 | AF36: =AE36*$P$7 -> 8.717 | AG36: =ROUND(AF36,2) -> 8.72 | AI36: =ROUND(AO36,2) -> 140 | AK36: =IF($AD$3,AM36+AG36,AM36) -> 140 | AM36: =IF($AD$4,X36-($AM$7/100*X36),X36) -> 140 | AO36: =IF($AD$5,AK36-((AK36*1.18031)-AK36),AK36) -> 140
C37: Герметики KRONbuild | O37: Герметики | Q37: =IF(P37>18,"ПЕРЕБОР","-") -> -
A38: SUT80 | C38: Герметик универсальный (бесцветный) 80 мл | D38: 80 | E38: - | F38: 12 | G38: =AI38 -> 120 | I38: =H38*F38 -> 0 | J38: =G38*I38 -> 0 | L38: 4660447835984 | M38: 4673743524407 | P38: =$P$9 -> 0 | Q38: =IF(P38>18,"ПЕРЕБОР","-") -> - | R38: 96 | T38: 1.25 | U38: =R38*T38 -> 120 | V38: =P38*0.01 -> 0 | W38: =U38-(U38*V38) -> 120 | X38: =ROUND(W38,2) -> 120 | AA38: 0.96 | AB38: =H38*AA38 -> 0 | AC38: =AB38*$P$7 -> 0 | AD38: =AA38/F38 -> 0.08 | AE38: =ROUND(AD38,3) -> 0.08 | AF38: =AE38*$P$7 -> 1.84 | AG38: =ROUND(AF38,2) -> 1.84 | AI38: =ROUND(AO38,2) -> 120 | AK38: =IF($AD$3,AM38+AG38,AM38) -> 120 | AM38: =IF($AD$4,X38-($AM$7/100*X38),X38) -> 120 | AO38: =IF($AD$5,AK38-((AK38*1.18031)-AK38),AK38) -> 120
A39: SUW80 | C39: Герметик универсальный (белый) 80 мл | D39: 80 | E39: - | F39: 12 | G39: =AI39 -> 120 | I39: =H39*F39 -> 0 | J39: =G39*I39 -> 0 | L39: 4660447835960 | M39: 4673743524414 | P39: =$P$9 -> 0 | Q39: =IF(P39>18,"ПЕРЕБОР","-") -> - | R39: 96 | T39: 1.25 | U39: =R39*T39 -> 120 | V39: =P39*0.01 -> 0 | W39: =U39-(U39*V39) -> 120 | X39: =ROUND(W39,2) -> 120 | AA39: 0.96 | AB39: =H39*AA39 -> 0 | AC39: =AB39*$P$7 -> 0 | AD39: =AA39/F39 -> 0.08 | AE39: =ROUND(AD39,3) -> 0.08 | AF39: =AE39*$P$7 -> 1.84 | AG39: =ROUND(AF39,2) -> 1.84 | AI39: =ROUND(AO39,2) -> 120 | AK39: =IF($AD$3,AM39+AG39,AM39) -> 120 | AM39: =IF($AD$4,X39-($AM$7/100*X39),X39) -> 120 | AO39: =IF($AD$5,AK39-((AK39*1.18031)-AK39),AK39) -> 120
A40: SST80 | C40: Герметик санитарный (бесцветный) 80 мл | D40: 80 | E40: - | F40: 12 | G40: =AI40 -> 122.5 | I40: =H40*F40 -> 0 | J40: =G40*I40 -> 0 | L40: 4660447835946 | M40: 4673743524421 | P40: =$P$9 -> 0 | Q40: =IF(P40>18,"ПЕРЕБОР","-") -> - | R40: 98 | T40: 1.25 | U40: =R40*T40 -> 122.5 | V40: =P40*0.01 -> 0 | W40: =U40-(U40*V40) -> 122.5 | X40: =ROUND(W40,2) -> 122.5 | AA40: 0.96 | AB40: =H40*AA40 -> 0 | AC40: =AB40*$P$7 -> 0 | AD40: =AA40/F40 -> 0.08 | AE40: =ROUND(AD40,3) -> 0.08 | AF40: =AE40*$P$7 -> 1.84 | AG40: =ROUND(AF40,2) -> 1.84 | AI40: =ROUND(AO40,2) -> 122.5 | AK40: =IF($AD$3,AM40+AG40,AM40) -> 122.5 | AM40: =IF($AD$4,X40-($AM$7/100*X40),X40) -> 122.5 | AO40: =IF($AD$5,AK40-((AK40*1.18031)-AK40),AK40) -> 122.5
A41: SSW80 | C41: Герметик санитарный (белый) 80 мл | D41: 80 | E41: - | F41: 12 | G41: =AI41 -> 122.5 | I41: =H41*F41 -> 0 | J41: =G41*I41 -> 0 | L41: 4660447835922 | M41: 4673743524438 | P41: =$P$9 -> 0 | Q41: =IF(P41>18,"ПЕРЕБОР","-") -> - | R41: 98 | T41: 1.25 | U41: =R41*T41 -> 122.5 | V41: =P41*0.01 -> 0 | W41: =U41-(U41*V41) -> 122.5 | X41: =ROUND(W41,2) -> 122.5 | AA41: 0.96 | AB41: =H41*AA41 -> 0 | AC41: =AB41*$P$7 -> 0 | AD41: =AA41/F41 -> 0.08 | AE41: =ROUND(AD41,3) -> 0.08 | AF41: =AE41*$P$7 -> 1.84 | AG41: =ROUND(AF41,2) -> 1.84 | AI41: =ROUND(AO41,2) -> 122.5 | AK41: =IF($AD$3,AM41+AG41,AM41) -> 122.5 | AM41: =IF($AD$4,X41-($AM$7/100*X41),X41) -> 122.5 | AO41: =IF($AD$5,AK41-((AK41*1.18031)-AK41),AK41) -> 122.5
A42: SNT60 | C42: Герметик силиконовый нейтральный (бесцветный) 600 мл. | D42: 550 | E42: - | F42: 20 | G42: =AI42 -> 298.75 | I42: =H42*F42 -> 0 | J42: =G42*I42 -> 0 | L42: 4660447835908 | M42: 4673743522335 | P42: =$P$9 -> 0 | Q42: =IF(P42>18,"ПЕРЕБОР","-") -> - | R42: 239 | T42: 1.25 | U42: =R42*T42 -> 298.75 | V42: =P42*0.01 -> 0 | W42: =U42-(U42*V42) -> 298.75 | X42: =ROUND(W42,2) -> 298.75 | AA42: 11.4 | AB42: =H42*AA42 -> 0 | AC42: =AB42*$P$7 -> 0 | AD42: =AA42/F42 -> 0.57 | AE42: =ROUND(AD42,3) -> 0.57 | AF42: =AE42*$P$7 -> 13.11 | AG42: =ROUND(AF42,2) -> 13.11 | AI42: =ROUND(AO42,2) -> 298.75 | AK42: =IF($AD$3,AM42+AG42,AM42) -> 298.75 | AM42: =IF($AD$4,X42-($AM$7/100*X42),X42) -> 298.75 | AO42: =IF($AD$5,AK42-((AK42*1.18031)-AK42),AK42) -> 298.75
...

Sheet Описание продукции
B2: Профессиональная монтажная пена KRONbuild MASTERS 80 (Лето, Зима) | D2: KRONbuild Masters профессиональная монтажная пена с превосходной структурой ячеек и хорошей механической прочностью, данная линейка монтажной пены KRONbuild Masters подходит для выполнения таких работ как: – монтажа окон и дверей; – заполнения швов и зазоров; – пустот и сквозных трещин; – изоляции линий горячего и холодного водоснабжения. | E2: • Зима –18° до 30° С. Лето от +5 до + 30° С. • Выход до 80 литров • Объем: 850 мл • Вес: 1000 гр. • Срок годности 18 месяцев
B3: Профессиональная монтажная пена KRONbuild HANDGUN 65 (Всесезонная) | D3: Профессиональная монтажная пена KRONbuild HANDGUN 65 можно использовать как с пистолетом для пены, так и как бытовую пену с трубочкой, подходит для выполнения таких общестроительных работ, как: – обеспечения тепло- и звукоизоляции; – заполнение трещин в холодных помещениях (утепление) и щелей в кровельных материалах; – пеной заделывают места примыкания вытяжек и кондиционеров, щели между трубами; – заполнение пустот вокруг труб отопления, водопроводных труб, на стыках и сгибах, заполнения пустот в стенах. | E3: • Зима от –18°до +30° С. Лето от +5 до +30°С. • Выход до 65 литров • Объём: 850 мл • Вес: 800 гр. • Срок годности 18 месяцев
